Workbook

Sheet groupe
A1: ETU003097 | B1: ANDRIANIAINA Diay Nathan
A2: ETU003117 | B2: KOTONIRINA Hardy Fleurys
A3: ETU003150 | B3: RAKOTOBE Tojonirina Ravanona
A4: ETU003166 | B4: RAMANANKIRAHINA Tsitohaina Berthin

Sheet liste des taches
A1: Ligne | B1: Catégorie | C1: Module | D1: Page | E1: Tâche | F1: Type | G1: Qui | H1: Estimation (min) | I1: Temps passé | J1: Reste à faire | K1: Avancement
A2: 1 | B2: Initialisation | C2: TileServer GL | E2: Dockeriser TileServer GL | F2: Configuration | G2: ETU003150 | H2: 45 | I2: 45 | J2: =H2-I2 -> 0 | K2: =I2/(I2+J2) -> 1
A3: 2 | B3: Initialisation | C3: TileServer GL | E3: Telecharger tuiles Antananarivo (.mbtiles) | F3: Telechargement | G3: ETU003097 | H3: 60 | I3: 30 | J3: =H3-I3 -> 30 | K3: =I3/(I3+J3) -> 0.5
A4: 3 | B4: Initialisation | C4: Angular Setup | E4: Initialiser projet Angular avec routing (docker) | F4: Developpement | G4: ETU003097 | H4: 60 | I4: 60 | J4: =H4-I4 -> 0 | K4: =I4/(I4+J4) -> 1
A5: 4 | B5: Initialisation | C5: Carte | D5: map | E5: Component Map avec Leaflet + tuiles offline | F5: Composant | G5: ETU003150 | H5: 80 | I5: 80 | J5: =H5-I5 -> 0 | K5: =I5/(I5+J5) -> 1
A6: 5 | B6: Initialisation | C6: Carte | D6: map | E6: Integration geolocalisation HTML5 | F6: Composant | G6: ETU003117 | H6: 40 | I6: 30 | J6: =H6-I6 -> 10 | K6: =I6/(I6+J6) -> 0.75
A7: 6 | B7: Initialisation | C7: Carte | D7: map | E7: Marqueurs interactifs signalements | F7: Composant | G7: ETU003097 | H7: 50 | I7: 30 | J7: =H7-I7 -> 20 | K7: =I7/(I7+J7) -> 0.6
A8: 7 | B8: Initialisation | C8: Ionic Setup | E8: Initialiser projet Ionic Vue | F8: Configuration | G8: ETU003166 | H8: 60 | I8: 0 | J8: =H8-I8 -> 60 | K8: =I8/(I8+J8) -> 0
A9: 8 | B9: Initialisation | C9: Carte Mobile | E9: Integration plugin maps Ionic + tuiles offline | F9: Composant | G9: ETU003166 | H9: 60 | I9: 60 | J9: =H9-I9 -> 0 | K9: =I9/(I9+J9) -> 1
A10: 9 | B10: Initialisation | C10: Carte Mobile | D10: map | E10: GPS en temps reel avec suivi position | F10: Composant | G10: ETU003150 | H10: 45 | I10: 0 | J10: =H10-I10 -> 45 | K10: =I10/(I10+J10) -> 0
A11: 10 | B11: Front-office web | C11: Firebase | E11: Initialiser projet Firebase (Auth + Firestore) | F11: Configuration | G11: ETU003117 | H11: 30 | I11: 30 | J11: =H11-I11 -> 0 | K11: =I11/(I11+J11) -> 1
A12: 11 | B12: Front-office web | C12: Firebase | E12: Configurer regles de securite Firestore | F12: Securite | G12: ETU003166 | H12: 30 | I12: 30 | J12: =H12-I12 -> 0 | K12: =I12/(I12+J12) -> 1
A13: 12 | B13: Front-office web | C13: Firebase | E13: Modele Firestore signalements (collections + champs) | F13: Base de donnees | G13: ETU003166 | H13: 30 | I13: 0 | J13: =H13-I13 -> 30 | K13: =I13/(I13+J13) -> 0
A14: 13 | B14: Front-office web | C14: Ionic Setup | E14: Configurer Firebase SDK mobile | F14: Configuration | G14: ETU003150 | H14: 35 | I14: 0 | J14: =H14-I14 -> 35 | K14: =I14/(I14+J14) -> 0
A15: 14 | B15: Front-office web | C15: Ionic Setup | E15: Mettre en place AsyncStorage pour donnees locales | F15: Configuration | G15: ETU003117 | H15: 30 | I15: 0 | J15: =H15-I15 -> 30 | K15: =I15/(I15+J15) -> 0
A16: 15 | B16: Front-office web | C16: Auth Mobile | D16: login | E16: Page login mobile (email/password) | F16: Composant | G16: ETU003097 | H16: 40 | I16: 40 | J16: =H16-I16 -> 0 | K16: =I16/(I16+J16) -> 1
A17: 16 | B17: Front-office web | C17: Auth Mobile | E17: Persistance session avec AsyncStorage | F17: Composant | G17: ETU003166 | H17: 25 | I17: 0 | J17: =H17-I17 -> 25 | K17: =I17/(I17+J17) -> 0
A18: 17 | B18: Front-office web | C18: Auth Mobile | E18: Auto-login au demarrage de l'app | F18: Composant | G18: ETU003150 | H18: 20 | I18: 0 | J18: =H18-I18 -> 20 | K18: =I18/(I18+J18) -> 0
A19: 18 | B19: Front-office web | C19: Generateur ID | E19: Service LocalIDService (generation UUID) | F19: Service | G19: ETU003117 | H19: 35 | I19: 35 | J19: =H19-I19 -> 0 | K19: =I19/(I19+J19) -> 1
A20: 19 | B20: Front-office web | C20: Generateur ID | E20: Stockage ID local dans AsyncStorage | F20: Service | G20: ETU003097 | H20: 20 | I20: 0 | J20: =H20-I20 -> 20 | K20: =I20/(I20+J20) -> 0
A21: 20 | B21: Front-office web | C21: Signalements Mobile | D21: map | E21: Formulaire avec photo (Camera API) | F21: Composant | G21: ETU003117 | H21: 60 | I21: 0 | J21: =H21-I21 -> 60 | K21: =I21/(I21+J21) -> 0
A22: 21 | B22: Front-office web | C22: Signalements Mobile | D22: map | E22: Enregistrement geolocalisation precise | F22: Composant | G22: ETU003097 | H22: 40 | I22: 0 | J22: =H22-I22 -> 40 | K22: =I22/(I22+J22) -> 0
A23: 22 | B23: Front-office web | C23: Signalements Mobile | D23: map | E23: Service d'envoi signalement vers Firebase | F23: Service | G23: ETU003117 | H23: 40 | I23: 0 | J23: =H23-I23 -> 40 | K23: =I23/(I23+J23) -> 0
A24: 23 | B24: Front-office web | C24: Synchronisation | E24: Ecran Sync manuelle (push/pull) | F24: Composant | G24: ETU003150 | H24: 45 | I24: 0 | J24: =H24-I24 -> 45 | K24: =I24/(I24+J24) -> 0
A25: 24 | B25: Front-office web | C25: Synchronisation | E25: Compression images avant envoi | F25: Service | G25: ETU003117 | H25: 30 | I25: 0 | J25: =H25-I25 -> 30 | K25: =I25/(I25+J25) -> 0
A26: 25 | B26: Front-office web | C26: Synchronisation | E26: Resolution conflits (last-write-win) | F26: Service | G26: ETU003097 | H26: 30 | I26: 0 | J26: =H26-I26 -> 30 | K26: =I26/(I26+J26) -> 0
A27: 26 | B27: Back-office web | C27: Docker | E27: Creer Dockerfile + backend Spring boot Java | F27: Configuration | G27: ETU003097 | H27: 60 | I27: 30 | J27: =H27-I27 -> 30 | K27: =I27/(I27+J27) -> 0.5
A28: 27 | B28: Back-office web | C28: Docker | E28: Configurer docker-compose.yml avec PostgreSQL + backend | F28: Configuration | G28: ETU003166 | H28: 30 | I28: 30 | J28: =H28-I28 -> 0 | K28: =I28/(I28+J28) -> 1
A29: 28 | B29: Back-office web | C29: PostgreSQL | E29: Initialiser base unique (web + ID generator) | F29: Base de donnees | G29: ETU003150 | H29: 50 | I29: 50 | J29: =H29-I29 -> 0 | K29: =I29/(I29+J29) -> 1
A30: 29 | B30: Back-office web | C30: PostgreSQL | E30: Creer tables : users ( tables dans la conception ) | F30: Base de donnees | G30: ETU003097 | H30: 45 | I30: 45 | J30: =H30-I30 -> 0 | K30: =I30/(I30+J30) -> 1
A31: 30 | B31: Back-office web | C31: Authentification | E31: Modele User PostgreSQL (champs + index) | F31: Metier | G31: ETU003150 | H31: 30 | I31: 0 | J31: =H31-I31 -> 30 | K31: =I31/(I31+J31) -> 0
A32: 31 | B32: Back-office web | C32: Authentification | D32: inscription | E32: API Inscription Web (POST /register) avec validation email | F32: Metier | G32: ETU003117 | H32: 40 | I32: 0 | J32: =H32-I32 -> 40 | K32: =I32/(I32+J32) -> 0
A33: 32 | B33: Back-office web | C33: Authentification | D33: login | E33: API Login Web (POST /login) avec generation JWT | F33: Metier | G33: ETU003097 | H33: 45 | I33: 45 | J33: =H33-I33 -> 0 | K33: =I33/(I33+J33) -> 1
A34: 33 | B34: Back-office web | C34: Authentification | D34: login | E34: Swagger pour generateur d'identification | F34: Metier | G34: ETU003097 | H34: 15 | I34: 15 | J34: =H34-I34 -> 0 | K34: =I34/(I34+J34) -> 1
A35: 34 | B35: Back-office web | C35: Authentification | D35: login | E35: API Login Mobile-only (POST /mobile-login) | F35: Metier | G35: ETU003166 | H35: 30 | I35: 0 | J35: =H35-I35 -> 30 | K35: =I35/(I35+J35) -> 0
A36: 35 | B36: Back-office web | C36: Authentification | D36: login | E36: Middleware verification JWT pour routes protegees | F36: Metier | G36: ETU003150 | H36: 40 | I36: 0 | J36: =H36-I36 -> 40 | K36: =I36/(I36+J36) -> 0
A37: 36 | B37: Back-office web | C37: Authentification | D37: accueil | E37: Refresh token et blacklist token (logout) | F37: Metier | G37: ETU003117 | H37: 30 | I37: 0 | J37: =H37-I37 -> 30 | K37: =I37/(I37+J37) -> 0
A38: 37 | B38: Back-office web | C38: Generateur ID | D38: login | E38: Table local_ids (id, user_id, local_id, device_id, status) | F38: Metier | G38: ETU003097 | H38: 25 | I38: 0 | J38: =H38-I38 -> 25 | K38: =I38/(I38+J38) -> 0
A39: 38 | B39: Back-office web | C39: Generateur ID | D39: login | E39: API Generation ID local (POST /generate-local-id) | F39: Metier | G39: ETU003166 | H39: 30 | I39: 30 | J39: =H39-I39 -> 0 | K39: =I39/(I39+J39) -> 1
A40: 39 | B40: Back-office web | C40: Generateur ID | D40: login | E40: API Recuperation IDs en attente (GET /pending-ids) | F40: Metier | G40: ETU003150 | H40: 20 | I40: 20 | J40: =H40-I40 -> 0 | K40: =I40/(I40+J40) -> 1
...

Sheet Recap
A2: Qui | B2: SUM of Estimation (min) | C2: SUM of Temps passé | D2: SUM of Reste à faire
A3: ETU003097 | B3: 785 | C3: 295 | D3: 490
A4: ETU003117 | B4: 710 | C4: 155 | D4: 555
A5: ETU003150 | B5: 705 | C5: 240 | D5: 465
A6: ETU003166 | B6: 655 | C6: 165 | D6: 490
A7: (vide)
A8: Total général | B8: 2855 | C8: 855 | D8: 2000
A12: Avancement | B12: =avancement!D2 -> 0.29947461

Sheet avancement
A1: estimation total | B1: temps passé total | C1: reste à faire total | D1: avancement | E1: estimation total
A2: =SUM('liste des taches'!H:H) -> 2855 | B2: =SUM('liste des taches'!I:I) -> 855 | C2: =SUM('liste des taches'!J:J) -> 2000 | D2: =(B2/(B2+C2)) -> 0.29947461 | E2: =SUM('liste des taches'!L:L) -> 0
C3: =C2/60 -> 33.333333 | D3: heure

Sheet detail_avancement
A1: Ligne | B1: Total | C1: 46048 | D1: 46049 | E1: 46050
A2: 1 | B2: =SUM(D2:P2) -> 45 | D2: 45
A3: 2 | B3: =SUM(D3:P3) -> 0 | D3: 0
A4: 3 | B4: =SUM(D4:P4) -> 60 | C4: 20 | D4: 60
A5: 4 | B5: =SUM(D5:P5) -> 0 | D5: 0
A6: 5 | B6: =SUM(D6:P6) -> 30 | D6: 30
A7: 6 | B7: =SUM(D7:P7) -> 30 | D7: 30
A8: 7 | B8: =SUM(D8:P8) -> 0 | D8: 0
A9: 8 | B9: =SUM(D9:P9) -> 60 | D9: 60
A10: 9 | B10: =SUM(D10:P10) -> 0 | D10: 0
A11: 10 | B11: =SUM(D11:P11) -> 30 | D11: 30
A12: 11 | B12: =SUM(D12:P12) -> 30 | D12: 30
A13: 12 | B13: =SUM(D13:P13) -> 0 | D13: 0
A14: 13 | B14: =SUM(D14:P14) -> 0 | D14: 0
A15: 14 | B15: =SUM(D15:P15) -> 0 | D15: 0
A16: 15 | B16: =SUM(D16:P16) -> 40 | D16: 40
... A70: 69 | B70: =SUM(D70:P70) -> 0 | D70: 0
